Workbook

Sheet Dashboard
A1: Aros Media Dashboard
D8: Videos Produced | E8: Total Production Cost | F8: Total GMV | G8: Total Commission | H8: Total Profit | I8: ROI | J8: Total Orders | K8: Cost Per Order
D9: =COUNT('Video Database'!A:A) -> 1392 | E9: =sum('Video Database'!H:H) -> 635.9793 | F9: =SUM('Performance Data'!F:F) -> 1428.83 | G9: =SUM('Performance Data'!J:J) -> 200.639 | H9: =SUM('Performance Data'!S:S) -> -435.3403 | I9: =Dashboard!H9/Dashboard!E9 -> -0.68451961 | J9: =SUM('Performance Data'!G:G) -> 68 | K9: =E9/J9 -> 9.3526368

Sheet Management P&L
B2: Aros Media
B3: Management P&L Statement
B4: Revenue
B5: Direct Commissions | D5: =Dashboard!G9 -> 200.639
B6: Total Revenue | E6: =SUM(D5) -> 200.639
B8: Expenses
B9: Direct Production Expenses
B10: Creator Costs | C10: =-SUM('Video Database'!I2:I999) -> -578.163
B11: Editor Costs | C11: =-SUM('Video Database'!J2:J999) -> 0
B12: Platform Fees | C12: =-SUM('Video Database'!K2:K999) -> -57.8163
B13: Total Production Expenses | E13: =sum(C10:C12) -> -635.9793
B14: Gross Profit (Loss) | E14: =SUM(E6:E13) -> -435.3403
B15: Operating Expenses
B16: Account Costs | C16: =(-19.67-100-150-25-25-60) -> -379.67
B17: Failed Videos | C17: =-(66+16.5) -> -82.5
B18: Product Shipment | C18: -13.5
B19: Total Administrative Costs | D19: =SUM(C16:C18) -> -475.67
B20: Subscriptions
B21: Creator Hiring Platform Subscription | C21: =-(359.1+159.1) -> -518.2
B22: Editor Hiring Platform Subscription | C22: -69
B23: Google Workspace Subscription | C23: -4.01
B24: Domain Registration | C24: -12
B25: Total Subscription Costs | D25: =SUM(C21:C24) -> -603.21
B26: Product Sample Costs
B27: Goli Women's Complete Multi Gummy | C27: -5.6
B28: Medicube S.O.S Invisible Patch & Medicube No Cast Just Dew PDRN Sunscreen | C28: -32.16
B29: Jergens Natural Glow Hydra Gel Moisturizer | C29: -14.97
B30: Gruns Immun 13-in1 Immunity Gummies | C30: -8.99
B31: DR.DENT Purple Mouthwash | C31: -18.01
B32: Medicube Deoxyribose Scalp Serum | C32: -22.49
B33: Neuro Gum Watermlon Energy & Focus | C33: -26.49
B34: Taste Salud 2-in1 Skin & Beauty Drink Mix | C34: -21.99
B35: COSRX US AIRY LIGHT CLEAR SUNSCREEN STICK | C35: -21.45
B36: Bloom Nutrition Daily Hydration Sticks | C36: -9.99
B37: COSRX US Vitamin E Vitalizing Sunscreen | C37: -18.78
B38: COSRX US The Peptide Collagen Lifting Mask | C38: -11.69
... B42: TIRTIR Hydro UV Shield Sunscreen | C42: -12.23
B43: Total Product Sample Costs | D43: =SUM(C27:C42) -> -251.11
B44: Total Operating Expenses | E44: =SUM(D19:D43) -> -1329.99
B45: Total Operating Profit (Loss) | E45: =SUM(E14:E44) -> -1765.3303

Sheet Unit Economics
B2: Metric | C2: Calculation | D2: Result | E2: Interpretation
B3: Commission per Video | C3: Total Commission ÷ Videos | D3: =Dashboard!G9/Dashboard!D9 -> 0.14413721 | E3: Average video generates $0.14 in commission revenue
B4: Production Cost per Video | C4: Production Costs ÷ Videos | D4: =-Dashboard!E9/Dashboard!$D$9 -> -0.45688168 | E4: Average video costs $0.46 to produce
B5: Profit per Video | C5: Profit ÷ Videos | D5: =Dashboard!H9/Dashboard!$D$9 -> -0.31274447 | E5: Average video has a loss of $0.31
B6: Commission per Order | C6: Commission ÷ Orders | D6: =Dashboard!G9/Dashboard!$J$9 -> 2.9505735 | E6: Average order generates $2.95 in commission revenue
B7: Production Cost per Order | C7: Production Costs ÷ Orders | D7: =-Dashboard!E9/Dashboard!$J$9 -> -9.3526368 | E7: Average order has a $9.35 video production cost
B8: Profit per Order | C8: Profit ÷ Orders | D8: =Dashboard!H9/Dashboard!$J$9 -> -6.4020632 | E8: Average order has a loss of $6.40
B9: Overall ROI | C9: Total Profit ÷ Total Production Investment | D9: =Dashboard!H9/Dashboard!E9 -> -0.68451961 | E9: Aros Media lost $0.68 for every $1.00 invested into production costs
B10: Operating Margin | C10: Operating Profit (Loss) / Revenue | D10: ='Management P&L'!E45/Dashboard!G9 -> -8.7985402 | E10: Aros Media lost approximately $8.80 for every $1.00 of revenue after accounting for both production and operating expenses

Sheet Cost Structure
C2: Total Expenses | D2: =-'Management P&L'!E13+(-'Management P&L'!E44) -> 1965.9693
B4: Expense Category | C4: Expense | D4: Amount | E4: % of Total Expenses
B5: Production | C5: Creator Costs | D5: =SUM('Video Database'!I2:I1000) -> 578.163 | E5: =D5/D$2 -> 0.29408547
C6: Editor Costs | D6: 0 | E6: =D6/D$2 -> 0
C7: Platform Fees | D7: =SUM('Video Database'!K2:K1000) -> 57.8163 | E7: =D7/D$2 -> 0.029408547
B8: Total | D8: =SUM(D5:D7) -> 635.9793 | E8: =SUM(E5:E7) -> 0.32349401
B9: Operating | C9: Account Costs | D9: =-'Management P&L'!C16 -> 379.67 | E9: =D9/D$2 -> 0.19312102
C10: Failed Videos | D10: =-'Management P&L'!C17 -> 82.5 | E10: =D10/D$2 -> 0.041964033
C11: Product Shipment | D11: =-'Management P&L'!C18 -> 13.5 | E11: =D11/D$2 -> 0.0068668417
C12: Subscriptions | D12: =-'Management P&L'!D25 -> 603.21 | E12: =D12/D$2 -> 0.30682575
C13: Product Samples | D13: =-'Management P&L'!D43 -> 251.11 | E13: =D13/D$2 -> 0.12772834
B14: Total | D14: =SUM(D9:D13) -> 1329.99 | E14: =SUM(E9:E13) -> 0.67650599
B15: SUM | D15: =D14+D8 -> 1965.9693 | E15: =E14+E8 -> 1

Sheet Business Findings
A1: Aros Media Business Findings
B5: EXECUTIVE SUMMARY
B6: - Aros Media generated $200.64 in commission revenue against $1,965.97 in total expenses
B7: - Recorded an operating loss of $1,765.33
B8: - Subscriptions were the largest expense category, accounting for approximately 30.7% of total expenses
B9: - Profitability analysis identifies specifc products, creators, and content styles to investigate for future production decisions
B11: Prioritize high-performing products
B12: - Products such as JOYMODE Ignite Libido Support, IRIS Hormone Health Drink Mix, BetterAlt Shilajit Honey Sticks, tarte CC Color-Correct Tinted Serum, and Beast Bites Creatine Gummies generated the strongest profits and highest ROI.
B13: - Increase content production for these products based on their strong profit and ROI performance.
B15: Increase production for high-performing creators
B16: - Creators with consistently positive ROI should recieve a greater share of production resources.
B17: - Blakely was the only creator with positive ROI; prioritize additional production with this creator while monitoring performance.
B19: Reduce spending on underperforming content styles
... B34: - Reevaluating these subscriptions to reduce a major expense should be a top priority
C35: - Adjusting subscription tiers, switching to different platforms, etc.

Sheet Video Database
A1: Date Posted | B1: Month | C1: Week | D1: Creator | E1: Account | F1: Brand | G1: Product | H1: Total Cost: | I1: Creator Cost | J1: Editor Cost | K1: Platform Fee | L1: Video # | M1: Content Type
A2: 46179 | B2: =text(A2,"mmm yyyy") -> Jun 2026 | C2: =weeknum(A2) -> 23 | D2: Erin | E2: Account 4 | F2: Color Wow Hair | G2: Color Wow Quick Refresh and Styling Bundle | H2: =SUM(I2+J2+K2) -> 1.1 | I2: 1 | K2: =I2/10 -> 0.1 | L2: 1 | M2: Bottom of Funnel
A3: 46179 | B3: =text(A3,"mmm yyyy") -> Jun 2026 | C3: =weeknum(A3) -> 23 | D3: Erin | E3: Account 4 | F3: Color Wow Hair | G3: Color Wow Quick Refresh and Styling Bundle | H3: =SUM(I3+J3+K3) -> 1.1 | I3: 1 | K3: =I3/10 -> 0.1 | L3: =L2+1 -> 2 | M3: Bottom of Funnel
A4: 46179 | B4: =text(A4,"mmm yyyy") -> Jun 2026 | C4: =weeknum(A4) -> 23 | D4: Erin | E4: Account 4 | F4: Color Wow Hair | G4: Color Wow Quick Refresh and Styling Bundle | H4: =SUM(I4+J4+K4) -> 1.1 | I4: 1 | K4: =I4/10 -> 0.1 | L4: =L3+1 -> 3 | M4: Bottom of Funnel
A5: 46179 | B5: =text(A5,"mmm yyyy") -> Jun 2026 | C5: =weeknum(A5) -> 23 | D5: Erin | E5: Account 4 | F5: Color Wow Hair | G5: Color Wow Quick Refresh and Styling Bundle | H5: =SUM(I5+J5+K5) -> 1.1 | I5: 1 | K5: =I5/10 -> 0.1 | L5: =L4+1 -> 4 | M5: Bottom of Funnel
A6: 46179 | B6: =text(A6,"mmm yyyy") -> Jun 2026 | C6: =weeknum(A6) -> 23 | D6: Erin | E6: Account 4 | F6: Color Wow Hair | G6: Color Wow Quick Refresh and Styling Bundle | H6: =SUM(I6+J6+K6) -> 1.1 | I6: 1 | K6: =I6/10 -> 0.1 | L6: =L5+1 -> 5 | M6: Bottom of Funnel
A7: 46179 | B7: =text(A7,"mmm yyyy") -> Jun 2026 | C7: =weeknum(A7) -> 23 | D7: Erin | E7: Account 4 | F7: Color Wow Hair | G7: Color Wow Quick Refresh and Styling Bundle | H7: =SUM(I7+J7+K7) -> 1.1 | I7: 1 | K7: =I7/10 -> 0.1 | L7: =L6+1 -> 6 | M7: Bottom of Funnel
A8: 46179 | B8: =text(A8,"mmm yyyy") -> Jun 2026 | C8: =weeknum(A8) -> 23 | D8: Erin | E8: Account 4 | F8: Color Wow Hair | G8: Color Wow Quick Refresh and Styling Bundle | H8: =SUM(I8+J8+K8) -> 1.1 | I8: 1 | K8: =I8/10 -> 0.1 | L8: =L7+1 -> 7 | M8: Bottom of Funnel
A9: 46179 | B9: =text(A9,"mmm yyyy") -> Jun 2026 | C9: =weeknum(A9) -> 23 | D9: Erin | E9: Account 4 | F9: Color Wow Hair | G9: Color Wow Quick Refresh and Styling Bundle | H9: =SUM(I9+J9+K9) -> 1.1 | I9: 1 | K9: =I9/10 -> 0.1 | L9: =L8+1 -> 8 | M9: Bottom of Funnel
A10: 46179 | B10: =text(A10,"mmm yyyy") -> Jun 2026 | C10: =weeknum(A10) -> 23 | D10: Erin | E10: Account 4 | F10: Color Wow Hair | G10: Color Wow Quick Refresh and Styling Bundle | H10: =SUM(I10+J10+K10) -> 1.1 | I10: 1 | K10: =I10/10 -> 0.1 | L10: =L9+1 -> 9 | M10: Bottom of Funnel
A11: 46179 | B11: =text(A11,"mmm yyyy") -> Jun 2026 | C11: =weeknum(A11) -> 23 | D11: Erin | E11: Account 4 | F11: Color Wow Hair | G11: Color Wow Quick Refresh and Styling Bundle | H11: =SUM(I11+J11+K11) -> 1.1 | I11: 1 | K11: =I11/10 -> 0.1 | L11: =L10+1 -> 10 | M11: Bottom of Funnel
A12: 46179 | B12: =text(A12,"mmm yyyy") -> Jun 2026 | C12: =weeknum(A12) -> 23 | D12: Erin | E12: Account 4 | F12: Color Wow Hair | G12: Color Wow Quick Refresh and Styling Bundle | H12: =SUM(I12+J12+K12) -> 1.1 | I12: 1 | K12: =I12/10 -> 0.1 | L12: =L11+1 -> 11 | M12: Bottom of Funnel
A13: 46179 | B13: =text(A13,"mmm yyyy") -> Jun 2026 | C13: =weeknum(A13) -> 23 | D13: Erin | E13: Account 4 | F13: Color Wow Hair | G13: Color Wow Quick Refresh and Styling Bundle | H13: =SUM(I13+J13+K13) -> 1.1 | I13: 1 | K13: =I13/10 -> 0.1 | L13: =L12+1 -> 12 | M13: Bottom of Funnel
A14: 46179 | B14: =text(A14,"mmm yyyy") -> Jun 2026 | C14: =weeknum(A14) -> 23 | D14: Erin | E14: Account 4 | F14: Color Wow Hair | G14: Color Wow Quick Refresh and Styling Bundle | H14: =SUM(I14+J14+K14) -> 1.1 | I14: 1 | K14: =I14/10 -> 0.1 | L14: =L13+1 -> 13 | M14: Bottom of Funnel
... A1393: 46208 | B1393: =text(A1393,"mmm yyyy") -> Jul 2026 | C1393: =weeknum(A1393) -> 28 | D1393: Brittney | E1393: Account 4 | F1393: Gruns | G1393: Gruns Greens Popsicle Firecracker Gummies | H1393: =SUM(I1393+J1393+K1393) -> 0.11 | I1393: 0.1 | K1393: =I1393/10 -> 0.01 | L1393: =L1392+1 -> 1392 | M1393: Bottom of Funnel

Sheet Performance Data
A1: Video # | B1: Creator | C1: Account | D1: Product | E1: Total Cost | F1: GMV | G1: Orders | H1: Date Posted | I1: Date Updated | J1: Commission | K1: Clicks | L1: Impressions | M1: Views | N1: Avg Watch Time | O1: CTR | P1: CTOR | Q1: Comimission per Order | R1: GMV per Order | S1: Profit | T1: ROI | U1: Profit Margin | V1: Cost per Order | W1: Cost per Click | X1: Cost Per $100 GMV | Y1: Content Style
A2: 1 | B2: {=_xlfn.XLOOKUP(A2,'Video Database'!L:L,'Video Database'!D:D,"")} -> Erin | C2: {=_xlfn.XLOOKUP(A2,'Video Database'!L:L,'Video Database'!E:E,"")} -> Account 4 | D2: {=_xlfn.XLOOKUP(A2,'Video Database'!L:L,'Video Database'!G:G,"")} -> Color Wow Quick Refresh and Styling Bundle | E2: {=_xlfn.XLOOKUP(A2,'Video Database'!L:L,'Video Database'!H:H,"")} -> 1.1 | F2: 0 | G2: 0 | H2: {=_xlfn.XLOOKUP(A2,'Video Database'!L:L,'Video Database'!A:A,"")} -> 46179 | I2: 46201 | J2: 0 | L2: =M2 | O2: =iferror(K2/L2, NA()) -> #N/A | P2: =iferror(G2/K2, NA()) -> #N/A | Q2: =iferror(J2/G2,NA()) -> #N/A | R2: =iferror(F2/G2,NA()) -> #N/A | S2: =J2-E2 -> -1.1 | T2: =if(E2=0,"",S2/E2) -> -1 | U2: =iferror(S2/J2,na()) -> #N/A | V2: =if(G2=0,"",E2/G2) | W2: =if(K2=0,"",E2/K2) | X2: =if(F2=0,"",(E2/F2)*100) | Y2: {=_xlfn.XLOOKUP(A2,'Video Database'!L:L,'Video Database'!M:M,"")} -> Bottom of Funnel
A3: =A2+1 -> 2 | B3: {=_xlfn.XLOOKUP(A3,'Video Database'!L:L,'Video Database'!D:D,"")} -> Erin | C3: {=_xlfn.XLOOKUP(A3,'Video Database'!L:L,'Video Database'!E:E,"")} -> Account 4 | D3: {=_xlfn.XLOOKUP(A3,'Video Database'!L:L,'Video Database'!G:G,"")} -> Color Wow Quick Refresh and Styling Bundle | E3: {=_xlfn.XLOOKUP(A3,'Video Database'!L:L,'Video Database'!H:H,"")} -> 1.1 | F3: 0 | G3: 0 | H3: {=_xlfn.XLOOKUP(A3,'Video Database'!L:L,'Video Database'!A:A,"")} -> 46179 | I3: 46201 | J3: 0 | L3: =M3 | O3: =iferror(K3/L3, NA()) -> #N/A | P3: =iferror(G3/K3, NA()) -> #N/A | Q3: =iferror(J3/G3,NA()) -> #N/A | R3: =iferror(F3/G3,NA()) -> #N/A | S3: =J3-E3 -> -1.1 | T3: =if(E3=0,"",S3/E3) -> -1 | U3: =iferror(S3/J3,na()) -> #N/A | V3: =if(G3=0,"",E3/G3) | W3: =if(K3=0,"",E3/K3) | X3: =if(F3=0,"",(E3/F3)*100) | Y3: {=_xlfn.XLOOKUP(A3,'Video Database'!L:L,'Video Database'!M:M,"")} -> Bottom of Funnel
A4: =A3+1 -> 3 | B4: {=_xlfn.XLOOKUP(A4,'Video Database'!L:L,'Video Database'!D:D,"")} -> Erin | C4: {=_xlfn.XLOOKUP(A4,'Video Database'!L:L,'Video Database'!E:E,"")} -> Account 4 | D4: {=_xlfn.XLOOKUP(A4,'Video Database'!L:L,'Video Database'!G:G,"")} -> Color Wow Quick Refresh and Styling Bundle | E4: {=_xlfn.XLOOKUP(A4,'Video Database'!L:L,'Video Database'!H:H,"")} -> 1.1 | F4: 0 | G4: 0 | H4: {=_xlfn.XLOOKUP(A4,'Video Database'!L:L,'Video Database'!A:A,"")} -> 46179 | I4: 46201 | J4: 0 | L4: =M4 | O4: =iferror(K4/L4, NA()) -> #N/A | P4: =iferror(G4/K4, NA()) -> #N/A | Q4: =iferror(J4/G4,NA()) -> #N/A | R4: =iferror(F4/G4,NA()) -> #N/A | S4: =J4-E4 -> -1.1 | T4: =if(E4=0,"",S4/E4) -> -1 | U4: =iferror(S4/J4,na()) -> #N/A | V4: =if(G4=0,"",E4/G4) | W4: =if(K4=0,"",E4/K4) | X4: =if(F4=0,"",(E4/F4)*100) | Y4: {=_xlfn.XLOOKUP(A4,'Video Database'!L:L,'Video Database'!M:M,"")} -> Bottom of Funnel
A5: =A4+1 -> 4 | B5: {=_xlfn.XLOOKUP(A5,'Video Database'!L:L,'Video Database'!D:D,"")} -> Erin | C5: {=_xlfn.XLOOKUP(A5,'Video Database'!L:L,'Video Database'!E:E,"")} -> Account 4 | D5: {=_xlfn.XLOOKUP(A5,'Video Database'!L:L,'Video Database'!G:G,"")} -> Color Wow Quick Refresh and Styling Bundle | E5: {=_xlfn.XLOOKUP(A5,'Video Database'!L:L,'Video Database'!H:H,"")} -> 1.1 | F5: 0 | G5: 0 | H5: {=_xlfn.XLOOKUP(A5,'Video Database'!L:L,'Video Database'!A:A,"")} -> 46179 | I5: 46201 | J5: 0 | L5: =M5 | O5: =iferror(K5/L5, NA()) -> #N/A | P5: =iferror(G5/K5, NA()) -> #N/A | Q5: =iferror(J5/G5,NA()) -> #N/A | R5: =iferror(F5/G5,NA()) -> #N/A | S5: =J5-E5 -> -1.1 | T5: =if(E5=0,"",S5/E5) -> -1 | U5: =iferror(S5/J5,na()) -> #N/A | V5: =if(G5=0,"",E5/G5) | W5: =if(K5=0,"",E5/K5) | X5: =if(F5=0,"",(E5/F5)*100) | Y5: {=_xlfn.XLOOKUP(A5,'Video Database'!L:L,'Video Database'!M:M,"")} -> Bottom of Funnel
A6: =A5+1 -> 5 | B6: {=_xlfn.XLOOKUP(A6,'Video Database'!L:L,'Video Database'!D:D,"")} -> Erin | C6: {=_xlfn.XLOOKUP(A6,'Video Database'!L:L,'Video Database'!E:E,"")} -> Account 4 | D6: {=_xlfn.XLOOKUP(A6,'Video Database'!L:L,'Video Database'!G:G,"")} -> Color Wow Quick Refresh and Styling Bundle | E6: {=_xlfn.XLOOKUP(A6,'Video Database'!L:L,'Video Database'!H:H,"")} -> 1.1 | F6: 0 | G6: 0 | H6: {=_xlfn.XLOOKUP(A6,'Video Database'!L:L,'Video Database'!A:A,"")} -> 46179 | I6: 46201 | J6: 0 | L6: =M6 | O6: =iferror(K6/L6, NA()) -> #N/A | P6: =iferror(G6/K6, NA()) -> #N/A | Q6: =iferror(J6/G6,NA()) -> #N/A | R6: =iferror(F6/G6,NA()) -> #N/A | S6: =J6-E6 -> -1.1 | T6: =if(E6=0,"",S6/E6) -> -1 | U6: =iferror(S6/J6,na()) -> #N/A | V6: =if(G6=0,"",E6/G6) | W6: =if(K6=0,"",E6/K6) | X6: =if(F6=0,"",(E6/F6)*100) | Y6: {=_xlfn.XLOOKUP(A6,'Video Database'!L:L,'Video Database'!M:M,"")} -> Bottom of Funnel
A7: =A6+1 -> 6 | B7: {=_xlfn.XLOOKUP(A7,'Video Database'!L:L,'Video Database'!D:D,"")} -> Erin | C7: {=_xlfn.XLOOKUP(A7,'Video Database'!L:L,'Video Database'!E:E,"")} -> Account 4 | D7: {=_xlfn.XLOOKUP(A7,'Video Database'!L:L,'Video Database'!G:G,"")} -> Color Wow Quick Refresh and Styling Bundle | E7: {=_xlfn.XLOOKUP(A7,'Video Database'!L:L,'Video Database'!H:H,"")} -> 1.1 | F7: 0 | G7: 0 | H7: {=_xlfn.XLOOKUP(A7,'Video Database'!L:L,'Video Database'!A:A,"")} -> 46179 | I7: 46201 | J7: 0 | L7: =M7 | O7: =iferror(K7/L7, NA()) -> #N/A | P7: =iferror(G7/K7, NA()) -> #N/A | Q7: =iferror(J7/G7,NA()) -> #N/A | R7: =iferror(F7/G7,NA()) -> #N/A | S7: =J7-E7 -> -1.1 | T7: =if(E7=0,"",S7/E7) -> -1 | U7: =iferror(S7/J7,na()) -> #N/A | V7: =if(G7=0,"",E7/G7) | W7: =if(K7=0,"",E7/K7) | X7: =if(F7=0,"",(E7/F7)*100) | Y7: {=_xlfn.XLOOKUP(A7,'Video Database'!L:L,'Video Database'!M:M,"")} -> Bottom of Funnel
A8: =A7+1 -> 7 | B8: {=_xlfn.XLOOKUP(A8,'Video Database'!L:L,'Video Database'!D:D,"")} -> Erin | C8: {=_xlfn.XLOOKUP(A8,'Video Database'!L:L,'Video Database'!E:E,"")} -> Account 4 | D8: {=_xlfn.XLOOKUP(A8,'Video Database'!L:L,'Video Database'!G:G,"")} -> Color Wow Quick Refresh and Styling Bundle | E8: {=_xlfn.XLOOKUP(A8,'Video Database'!L:L,'Video Database'!H:H,"")} -> 1.1 | F8: 0 | G8: 0 | H8: {=_xlfn.XLOOKUP(A8,'Video Database'!L:L,'Video Database'!A:A,"")} -> 46179 | I8: 46201 | J8: 0 | L8: =M8 | O8: =iferror(K8/L8, NA()) -> #N/A | P8: =iferror(G8/K8, NA()) -> #N/A | Q8: =iferror(J8/G8,NA()) -> #N/A | R8: =iferror(F8/G8,NA()) -> #N/A | S8: =J8-E8 -> -1.1 | T8: =if(E8=0,"",S8/E8) -> -1 | U8: =iferror(S8/J8,na()) -> #N/A | V8: =if(G8=0,"",E8/G8) | W8: =if(K8=0,"",E8/K8) | X8: =if(F8=0,"",(E8/F8)*100) | Y8: {=_xlfn.XLOOKUP(A8,'Video Database'!L:L,'Video Database'!M:M,"")} -> Bottom of Funnel
A9: =A8+1 -> 8 | B9: {=_xlfn.XLOOKUP(A9,'Video Database'!L:L,'Video Database'!D:D,"")} -> Erin | C9: {=_xlfn.XLOOKUP(A9,'Video Database'!L:L,'Video Database'!E:E,"")} -> Account 4 | D9: {=_xlfn.XLOOKUP(A9,'Video Database'!L:L,'Video Database'!G:G,"")} -> Color Wow Quick Refresh and Styling Bundle | E9: {=_xlfn.XLOOKUP(A9,'Video Database'!L:L,'Video Database'!H:H,"")} -> 1.1 | F9: 0 | G9: 0 | H9: {=_xlfn.XLOOKUP(A9,'Video Database'!L:L,'Video Database'!A:A,"")} -> 46179 | I9: 46201 | J9: 0 | L9: =M9 | O9: =iferror(K9/L9, NA()) -> #N/A | P9: =iferror(G9/K9, NA()) -> #N/A | Q9: =iferror(J9/G9,NA()) -> #N/A | R9: =iferror(F9/G9,NA()) -> #N/A | S9: =J9-E9 -> -1.1 | T9: =if(E9=0,"",S9/E9) -> -1 | U9: =iferror(S9/J9,na()) -> #N/A | V9: =if(G9=0,"",E9/G9) | W9: =if(K9=0,"",E9/K9) | X9: =if(F9=0,"",(E9/F9)*100) | Y9: {=_xlfn.XLOOKUP(A9,'Video Database'!L:L,'Video Database'!M:M,"")} -> Bottom of Funnel
A10: =A9+1 -> 9 | B10: {=_xlfn.XLOOKUP(A10,'Video Database'!L:L,'Video Database'!D:D,"")} -> Erin | C10: {=_xlfn.XLOOKUP(A10,'Video Database'!L:L,'Video Database'!E:E,"")} -> Account 4 | D10: {=_xlfn.XLOOKUP(A10,'Video Database'!L:L,'Video Database'!G:G,"")} -> Color Wow Quick Refresh and Styling Bundle | E10: {=_xlfn.XLOOKUP(A10,'Video Database'!L:L,'Video Database'!H:H,"")} -> 1.1 | F10: 0 | G10: 0 | H10: {=_xlfn.XLOOKUP(A10,'Video Database'!L:L,'Video Database'!A:A,"")} -> 46179 | I10: 46201 | J10: 0 | L10: =M10 | O10: =iferror(K10/L10, NA()) -> #N/A | P10: =iferror(G10/K10, NA()) -> #N/A | Q10: =iferror(J10/G10,NA()) -> #N/A | R10: =iferror(F10/G10,NA()) -> #N/A | S10: =J10-E10 -> -1.1 | T10: =if(E10=0,"",S10/E10) -> -1 | U10: =iferror(S10/J10,na()) -> #N/A | V10: =if(G10=0,"",E10/G10) | W10: =if(K10=0,"",E10/K10) | X10: =if(F10=0,"",(E10/F10)*100) | Y10: {=_xlfn.XLOOKUP(A10,'Video Database'!L:L,'Video Database'!M:M,"")} -> Bottom of Funnel
A11: =A10+1 -> 10 | B11: {=_xlfn.XLOOKUP(A11,'Video Database'!L:L,'Video Database'!D:D,"")} -> Erin | C11: {=_xlfn.XLOOKUP(A11,'Video Database'!L:L,'Video Database'!E:E,"")} -> Account 4 | D11: {=_xlfn.XLOOKUP(A11,'Video Database'!L:L,'Video Database'!G:G,"")} -> Color Wow Quick Refresh and Styling Bundle | E11: {=_xlfn.XLOOKUP(A11,'Video Database'!L:L,'Video Database'!H:H,"")} -> 1.1 | F11: 0 | G11: 0 | H11: {=_xlfn.XLOOKUP(A11,'Video Database'!L:L,'Video Database'!A:A,"")} -> 46179 | I11: 46201 | J11: 0 | L11: =M11 | O11: =iferror(K11/L11, NA()) -> #N/A | P11: =iferror(G11/K11, NA()) -> #N/A | Q11: =iferror(J11/G11,NA()) -> #N/A | R11: =iferror(F11/G11,NA()) -> #N/A | S11: =J11-E11 -> -1.1 | T11: =if(E11=0,"",S11/E11) -> -1 | U11: =iferror(S11/J11,na()) -> #N/A | V11: =if(G11=0,"",E11/G11) | W11: =if(K11=0,"",E11/K11) | X11: =if(F11=0,"",(E11/F11)*100) | Y11: {=_xlfn.XLOOKUP(A11,'Video Database'!L:L,'Video Database'!M:M,"")} -> Bottom of Funnel
A12: =A11+1 -> 11 | B12: {=_xlfn.XLOOKUP(A12,'Video Database'!L:L,'Video Database'!D:D,"")} -> Erin | C12: {=_xlfn.XLOOKUP(A12,'Video Database'!L:L,'Video Database'!E:E,"")} -> Account 4 | D12: {=_xlfn.XLOOKUP(A12,'Video Database'!L:L,'Video Database'!G:G,"")} -> Color Wow Quick Refresh and Styling Bundle | E12: {=_xlfn.XLOOKUP(A12,'Video Database'!L:L,'Video Database'!H:H,"")} -> 1.1 | F12: 0 | G12: 0 | H12: {=_xlfn.XLOOKUP(A12,'Video Database'!L:L,'Video Database'!A:A,"")} -> 46179 | I12: 46201 | J12: 0 | L12: =M12 | O12: =iferror(K12/L12, NA()) -> #N/A | P12: =iferror(G12/K12, NA()) -> #N/A | Q12: =iferror(J12/G12,NA()) -> #N/A | R12: =iferror(F12/G12,NA()) -> #N/A | S12: =J12-E12 -> -1.1 | T12: =if(E12=0,"",S12/E12) -> -1 | U12: =iferror(S12/J12,na()) -> #N/A | V12: =if(G12=0,"",E12/G12) | W12: =if(K12=0,"",E12/K12) | X12: =if(F12=0,"",(E12/F12)*100) | Y12: {=_xlfn.XLOOKUP(A12,'Video Database'!L:L,'Video Database'!M:M,"")} -> Bottom of Funnel
A13: =A12+1 -> 12 | B13: {=_xlfn.XLOOKUP(A13,'Video Database'!L:L,'Video Database'!D:D,"")} -> Erin | C13: {=_xlfn.XLOOKUP(A13,'Video Database'!L:L,'Video Database'!E:E,"")} -> Account 4 | D13: {=_xlfn.XLOOKUP(A13,'Video Database'!L:L,'Video Database'!G:G,"")} -> Color Wow Quick Refresh and Styling Bundle | E13: {=_xlfn.XLOOKUP(A13,'Video Database'!L:L,'Video Database'!H:H,"")} -> 1.1 | F13: 0 | G13: 0 | H13: {=_xlfn.XLOOKUP(A13,'Video Database'!L:L,'Video Database'!A:A,"")} -> 46179 | I13: 46201 | J13: 0 | L13: =M13 | O13: =iferror(K13/L13, NA()) -> #N/A | P13: =iferror(G13/K13, NA()) -> #N/A | Q13: =iferror(J13/G13,NA()) -> #N/A | R13: =iferror(F13/G13,NA()) -> #N/A | S13: =J13-E13 -> -1.1 | T13: =if(E13=0,"",S13/E13) -> -1 | U13: =iferror(S13/J13,na()) -> #N/A | V13: =if(G13=0,"",E13/G13) | W13: =if(K13=0,"",E13/K13) | X13: =if(F13=0,"",(E13/F13)*100) | Y13: {=_xlfn.XLOOKUP(A13,'Video Database'!L:L,'Video Database'!M:M,"")} -> Bottom of Funnel
A14: =A13+1 -> 13 | B14: {=_xlfn.XLOOKUP(A14,'Video Database'!L:L,'Video Database'!D:D,"")} -> Erin | C14: {=_xlfn.XLOOKUP(A14,'Video Database'!L:L,'Video Database'!E:E,"")} -> Account 4 | D14: {=_xlfn.XLOOKUP(A14,'Video Database'!L:L,'Video Database'!G:G,"")} -> Color Wow Quick Refresh and Styling Bundle | E14: {=_xlfn.XLOOKUP(A14,'Video Database'!L:L,'Video Database'!H:H,"")} -> 1.1 | F14: 0 | G14: 0 | H14: {=_xlfn.XLOOKUP(A14,'Video Database'!L:L,'Video Database'!A:A,"")} -> 46179 | I14: 46201 | J14: 0 | L14: =M14 | O14: =iferror(K14/L14, NA()) -> #N/A | P14: =iferror(G14/K14, NA()) -> #N/A | Q14: =iferror(J14/G14,NA()) -> #N/A | R14: =iferror(F14/G14,NA()) -> #N/A | S14: =J14-E14 -> -1.1 | T14: =if(E14=0,"",S14/E14) -> -1 | U14: =iferror(S14/J14,na()) -> #N/A | V14: =if(G14=0,"",E14/G14) | W14: =if(K14=0,"",E14/K14) | X14: =if(F14=0,"",(E14/F14)*100) | Y14: {=_xlfn.XLOOKUP(A14,'Video Database'!L:L,'Video Database'!M:M,"")} -> Bottom of Funnel
... A46: =A45+1 -> 45 | B46: {=_xlfn.XLOOKUP(A46,'Video Database'!L:L,'Video Database'!D:D,"")} -> Erin | C46: {=_xlfn.XLOOKUP(A46,'Video Database'!L:L,'Video Database'!E:E,"")} -> Account 4 | D46: {=_xlfn.XLOOKUP(A46,'Video Database'!L:L,'Video Database'!G:G,"")} -> Stainless Steel Gua Sha | E46: {=_xlfn.XLOOKUP(A46,'Video Database'!L:L,'Video Database'!H:H,"")} -> 1.1 | F46: 0 | G46: 0 | H46: {=_xlfn.XLOOKUP(A46,'Video Database'!L:L,'Video Database'!A:A,"")} -> 46181 | I46: 46201 | J46: 0 | L46: =M46 | O46: =iferror(K46/L46, NA()) -> #N/A | P46: =iferror(G46/K46, NA()) -> #N/A | Q46: =iferror(J46/G46,NA()) -> #N/A | R46: =iferror(F46/G46,NA()) -> #N/A | S46: =J46-E46 -> -1.1 | T46: =if(E46=0,"",S46/E46) -> -1 | U46: =iferror(S46/J46,na()) -> #N/A | V46: =if(G46=0,"",E46/G46) | W46: =if(K46=0,"",E46/K46) | X46: =if(F46=0,"",(E46/F46)*100) | Y46: {=_xlfn.XLOOKUP(A46,'Video Database'!L:L,'Video Database'!M:M,"")} -> Bottom of Funnel
A47: =A46+1 -> 46 | B47: {=_xlfn.XLOOKUP(A47,'Video Database'!L:L,'Video Database'!D:D,"")} -> Erin | C47: {=_xlfn.XLOOKUP(A47,'Video Database'!L:L,'Video Database'!E:E,"")} -> Account 4 | D47: {=_xlfn.XLOOKUP(A47,'Video Database'!L:L,'Video Database'!G:G,"")} -> Stainless Steel Gua Sha | E47: {=_xlfn.XLOOKUP(A47,'Video Database'!L:L,'Video Database'!H:H,"")} -> 1.1 | F47: 17.16 | G47: 1 | H47: {=_xlfn.XLOOKUP(A47,'Video Database'!L:L,'Video Database'!A:A,"")} -> 46181 | I47: 46201 | J47: 1.04 | K47: 3 | L47: =M47 -> 100 | M47: 100 | O47: =iferror(K47/L47, NA()) -> 0.03 | P47: =iferror(G47/K47, NA()) -> 0.33333333 | Q47: =iferror(J47/G47,NA()) -> 1.04 | R47: =iferror(F47/G47,NA()) -> 17.16 | S47: =J47-E47 -> -0.06 | T47: =if(E47=0,"",S47/E47) -> -0.054545455 | U47: =iferror(S47/J47,na()) -> -0.057692308 | V47: =if(G47=0,"",E47/G47) -> 1.1 | W47: =if(K47=0,"",E47/K47) -> 0.36666667 | X47: =if(F47=0,"",(E47/F47)*100) -> 6.4102564 | Y47: {=_xlfn.XLOOKUP(A47,'Video Database'!L:L,'Video Database'!M:M,"")} -> Bottom of Funnel
A48: =A47+1 -> 47 | B48: {=_xlfn.XLOOKUP(A48,'Video Database'!L:L,'Video Database'!D:D,"")} -> Erin | C48: {=_xlfn.XLOOKUP(A48,'Video Database'!L:L,'Video Database'!E:E,"")} -> Account 4 | D48: {=_xlfn.XLOOKUP(A48,'Video Database'!L:L,'Video Database'!G:G,"")} -> Stainless Steel Gua Sha | E48: {=_xlfn.XLOOKUP(A48,'Video Database'!L:L,'Video Database'!H:H,"")} -> 1.1 | F48: 0 | G48: 0 | H48: {=_xlfn.XLOOKUP(A48,'Video Database'!L:L,'Video Database'!A:A,"")} -> 46182 | I48: 46201 | J48: 0 | L48: =M48 | O48: =iferror(K48/L48, NA()) -> #N/A | P48: =iferror(G48/K48, NA()) -> #N/A | Q48: =iferror(J48/G48,NA()) -> #N/A | R48: =iferror(F48/G48,NA()) -> #N/A | S48: =J48-E48 -> -1.1 | T48: =if(E48=0,"",S48/E48) -> -1 | U48: =iferror(S48/J48,na()) -> #N/A | V48: =if(G48=0,"",E48/G48) | W48: =if(K48=0,"",E48/K48) | X48: =if(F48=0,"",(E48/F48)*100) | Y48: {=_xlfn.XLOOKUP(A48,'Video Database'!L:L,'Video Database'!M:M,"")} -> Bottom of Funnel
A49: =A48+1 -> 48 | B49: {=_xlfn.XLOOKUP(A49,'Video Database'!L:L,'Video Database'!D:D,"")} -> Erin | C49: {=_xlfn.XLOOKUP(A49,'Video Database'!L:L,'Video Database'!E:E,"")} -> Account 4 | D49: {=_xlfn.XLOOKUP(A49,'Video Database'!L:L,'Video Database'!G:G,"")} -> Stainless Steel Gua Sha | E49: {=_xlfn.XLOOKUP(A49,'Video Database'!L:L,'Video Database'!H:H,"")} -> 1.1 | F49: 0 | G49: 0 | H49: {=_xlfn.XLOOKUP(A49,'Video Database'!L:L,'Video Database'!A:A,"")} -> 46182 | I49: 46201 | J49: 0 | L49: =M49 | O49: =iferror(K49/L49, NA()) -> #N/A | P49: =iferror(G49/K49, NA()) -> #N/A | Q49: =iferror(J49/G49,NA()) -> #N/A | R49: =iferror(F49/G49,NA()) -> #N/A | S49: =J49-E49 -> -1.1 | T49: =if(E49=0,"",S49/E49) -> -1 | U49: =iferror(S49/J49,na()) -> #N/A | V49: =if(G49=0,"",E49/G49) | W49: =if(K49=0,"",E49/K49) | X49: =if(F49=0,"",(E49/F49)*100) | Y49: {=_xlfn.XLOOKUP(A49,'Video Database'!L:L,'Video Database'!M:M,"")} -> Bottom of Funnel
A50: =A49+1 -> 49 | B50: {=_xlfn.XLOOKUP(A50,'Video Database'!L:L,'Video Database'!D:D,"")} -> Erin | C50: {=_xlfn.XLOOKUP(A50,'Video Database'!L:L,'Video Database'!E:E,"")} -> Account 4 | D50: {=_xlfn.XLOOKUP(A50,'Video Database'!L:L,'Video Database'!G:G,"")} -> Stainless Steel Gua Sha | E50: {=_xlfn.XLOOKUP(A50,'Video Database'!L:L,'Video Database'!H:H,"")} -> 1.1 | F50: 0 | G50: 0 | H50: {=_xlfn.XLOOKUP(A50,'Video Database'!L:L,'Video Database'!A:A,"")} -> 46182 | I50: 46201 | J50: 0 | L50: =M50 | O50: =iferror(K50/L50, NA()) -> #N/A | P50: =iferror(G50/K50, NA()) -> #N/A | Q50: =iferror(J50/G50,NA()) -> #N/A | R50: =iferror(F50/G50,NA()) -> #N/A | S50: =J50-E50 -> -1.1 | T50: =if(E50=0,"",S50/E50) -> -1 | U50: =iferror(S50/J50,na()) -> #N/A | V50: =if(G50=0,"",E50/G50) | W50: =if(K50=0,"",E50/K50) | X50: =if(F50=0,"",(E50/F50)*100) | Y50: {=_xlfn.XLOOKUP(A50,'Video Database'!L:L,'Video Database'!M:M,"")} -> Bottom of Funnel
A51: =A50+1 -> 50 | B51: {=_xlfn.XLOOKUP(A51,'Video Database'!L:L,'Video Database'!D:D,"")} -> Erin | C51: {=_xlfn.XLOOKUP(A51,'Video Database'!L:L,'Video Database'!E:E,"")} -> Account 4 | D51: {=_xlfn.XLOOKUP(A51,'Video Database'!L:L,'Video Database'!G:G,"")} -> Stainless Steel Gua Sha | E51: {=_xlfn.XLOOKUP(A51,'Video Database'!L:L,'Video Database'!H:H,"")} -> 1.1 | F51: 0 | G51: 0 | H51: {=_xlfn.XLOOKUP(A51,'Video Database'!L:L,'Video Database'!A:A,"")} -> 46182 | I51: 46201 | J51: 0 | L51: =M51 | O51: =iferror(K51/L51, NA()) -> #N/A | P51: =iferror(G51/K51, NA()) -> #N/A | Q51: =iferror(J51/G51,NA()) -> #N/A | R51: =iferror(F51/G51,NA()) -> #N/A | S51: =J51-E51 -> -1.1 | T51: =if(E51=0,"",S51/E51) -> -1 | U51: =iferror(S51/J51,na()) -> #N/A | V51: =if(G51=0,"",E51/G51) | W51: =if(K51=0,"",E51/K51) | X51: =if(F51=0,"",(E51/F51)*100) | Y51: {=_xlfn.XLOOKUP(A51,'Video Database'!L:L,'Video Database'!M:M,"")} -> Bottom of Funnel
A52: =A51+1 -> 51 | B52: {=_xlfn.XLOOKUP(A52,'Video Database'!L:L,'Video Database'!D:D,"")} -> Erin | C52: {=_xlfn.XLOOKUP(A52,'Video Database'!L:L,'Video Database'!E:E,"")} -> Account 4 | D52: {=_xlfn.XLOOKUP(A52,'Video Database'!L:L,'Video Database'!G:G,"")} -> Stainless Steel Gua Sha | E52: {=_xlfn.XLOOKUP(A52,'Video Database'!L:L,'Video Database'!H:H,"")} -> 1.1 | F52: 0 | G52: 0 | H52: {=_xlfn.XLOOKUP(A52,'Video Database'!L:L,'Video Database'!A:A,"")} -> 46182 | I52: 46201 | J52: 0 | L52: =M52 | O52: =iferror(K52/L52, NA()) -> #N/A | P52: =iferror(G52/K52, NA()) -> #N/A | Q52: =iferror(J52/G52,NA()) -> #N/A | R52: =iferror(F52/G52,NA()) -> #N/A | S52: =J52-E52 -> -1.1 | T52: =if(E52=0,"",S52/E52) -> -1 | U52: =iferror(S52/J52,na()) -> #N/A | V52: =if(G52=0,"",E52/G52) | W52: =if(K52=0,"",E52/K52) | X52: =if(F52=0,"",(E52/F52)*100) | Y52: {=_xlfn.XLOOKUP(A52,'Video Database'!L:L,'Video Database'!M:M,"")} -> Bottom of Funnel
A53: =A52+1 -> 52 | B53: {=_xlfn.XLOOKUP(A53,'Video Database'!L:L,'Video Database'!D:D,"")} -> Erin | C53: {=_xlfn.XLOOKUP(A53,'Video Database'!L:L,'Video Database'!E:E,"")} -> Account 4 | D53: {=_xlfn.XLOOKUP(A53,'Video Database'!L:L,'Video Database'!G:G,"")} -> Stainless Steel Gua Sha | E53: {=_xlfn.XLOOKUP(A53,'Video Database'!L:L,'Video Database'!H:H,"")} -> 1.1 | F53: 0 | G53: 0 | H53: {=_xlfn.XLOOKUP(A53,'Video Database'!L:L,'Video Database'!A:A,"")} -> 46182 | I53: 46201 | J53: 0 | L53: =M53 | O53: =iferror(K53/L53, NA()) -> #N/A | P53: =iferror(G53/K53, NA()) -> #N/A | Q53: =iferror(J53/G53,NA()) -> #N/A | R53: =iferror(F53/G53,NA()) -> #N/A | S53: =J53-E53 -> -1.1 | T53: =if(E53=0,"",S53/E53) -> -1 | U53: =iferror(S53/J53,na()) -> #N/A | V53: =if(G53=0,"",E53/G53) | W53: =if(K53=0,"",E53/K53) | X53: =if(F53=0,"",(E53/F53)*100) | Y53: {=_xlfn.XLOOKUP(A53,'Video Database'!L:L,'Video Database'!M:M,"")} -> Bottom of Funnel
A54: =A53+1 -> 53 | B54: {=_xlfn.XLOOKUP(A54,'Video Database'!L:L,'Video Database'!D:D,"")} -> Erin | C54: {=_xlfn.XLOOKUP(A54,'Video Database'!L:L,'Video Database'!E:E,"")} -> Account 4 | D54: {=_xlfn.XLOOKUP(A54,'Video Database'!L:L,'Video Database'!G:G,"")} -> Stainless Steel Gua Sha | E54: {=_xlfn.XLOOKUP(A54,'Video Database'!L:L,'Video Database'!H:H,"")} -> 1.1 | F54: 0 | G54: 0 | H54: {=_xlfn.XLOOKUP(A54,'Video Database'!L:L,'Video Database'!A:A,"")} -> 46182 | I54: 46201 | J54: 0 | L54: =M54 | O54: =iferror(K54/L54, NA()) -> #N/A | P54: =iferror(G54/K54, NA()) -> #N/A | Q54: =iferror(J54/G54,NA()) -> #N/A | R54: =iferror(F54/G54,NA()) -> #N/A | S54: =J54-E54 -> -1.1 | T54: =if(E54=0,"",S54/E54) -> -1 | U54: =iferror(S54/J54,na()) -> #N/A | V54: =if(G54=0,"",E54/G54) | W54: =if(K54=0,"",E54/K54) | X54: =if(F54=0,"",(E54/F54)*100) | Y54: {=_xlfn.XLOOKUP(A54,'Video Database'!L:L,'Video Database'!M:M,"")} -> Bottom of Funnel
A55: =A54+1 -> 54 | B55: {=_xlfn.XLOOKUP(A55,'Video Database'!L:L,'Video Database'!D:D,"")} -> Erin | C55: {=_xlfn.XLOOKUP(A55,'Video Database'!L:L,'Video Database'!E:E,"")} -> Account 4 | D55: {=_xlfn.XLOOKUP(A55,'Video Database'!L:L,'Video Database'!G:G,"")} -> Stainless Steel Gua Sha | E55: {=_xlfn.XLOOKUP(A55,'Video Database'!L:L,'Video Database'!H:H,"")} -> 1.1 | F55: 0 | G55: 0 | H55: {=_xlfn.XLOOKUP(A55,'Video Database'!L:L,'Video Database'!A:A,"")} -> 46182 | I55: 46201 | J55: 0 | L55: =M55 | O55: =iferror(K55/L55, NA()) -> #N/A | P55: =iferror(G55/K55, NA()) -> #N/A | Q55: =iferror(J55/G55,NA()) -> #N/A | R55: =iferror(F55/G55,NA()) -> #N/A | S55: =J55-E55 -> -1.1 | T55: =if(E55=0,"",S55/E55) -> -1 | U55: =iferror(S55/J55,na()) -> #N/A | V55: =if(G55=0,"",E55/G55) | W55: =if(K55=0,"",E55/K55) | X55: =if(F55=0,"",(E55/F55)*100) | Y55: {=_xlfn.XLOOKUP(A55,'Video Database'!L:L,'Video Database'!M:M,"")} -> Bottom of Funnel
A56: =A55+1 -> 55 | B56: {=_xlfn.XLOOKUP(A56,'Video Database'!L:L,'Video Database'!D:D,"")} -> Erin | C56: {=_xlfn.XLOOKUP(A56,'Video Database'!L:L,'Video Database'!E:E,"")} -> Account 4 | D56: {=_xlfn.XLOOKUP(A56,'Video Database'!L:L,'Video Database'!G:G,"")} -> Stainless Steel Gua Sha | E56: {=_xlfn.XLOOKUP(A56,'Video Database'!L:L,'Video Database'!H:H,"")} -> 1.1 | F56: 0 | G56: 0 | H56: {=_xlfn.XLOOKUP(A56,'Video Database'!L:L,'Video Database'!A:A,"")} -> 46182 | I56: 46201 | J56: 0 | L56: =M56 | O56: =iferror(K56/L56, NA()) -> #N/A | P56: =iferror(G56/K56, NA()) -> #N/A | Q56: =iferror(J56/G56,NA()) -> #N/A | R56: =iferror(F56/G56,NA()) -> #N/A | S56: =J56-E56 -> -1.1 | T56: =if(E56=0,"",S56/E56) -> -1 | U56: =iferror(S56/J56,na()) -> #N/A | V56: =if(G56=0,"",E56/G56) | W56: =if(K56=0,"",E56/K56) | X56: =if(F56=0,"",(E56/F56)*100) | Y56: {=_xlfn.XLOOKUP(A56,'Video Database'!L:L,'Video Database'!M:M,"")} -> Bottom of Funnel
A57: =A56+1 -> 56 | B57: {=_xlfn.XLOOKUP(A57,'Video Database'!L:L,'Video Database'!D:D,"")} -> Erin | C57: {=_xlfn.XLOOKUP(A57,'Video Database'!L:L,'Video Database'!E:E,"")} -> Account 4 | D57: {=_xlfn.XLOOKUP(A57,'Video Database'!L:L,'Video Database'!G:G,"")} -> Stainless Steel Gua Sha | E57: {=_xlfn.XLOOKUP(A57,'Video Database'!L:L,'Video Database'!H:H,"")} -> 1.1 | F57: 0 | G57: 0 | H57: {=_xlfn.XLOOKUP(A57,'Video Database'!L:L,'Video Database'!A:A,"")} -> 46182 | I57: 46201 | J57: 0 | L57: =M57 | O57: =iferror(K57/L57, NA()) -> #N/A | P57: =iferror(G57/K57, NA()) -> #N/A | Q57: =iferror(J57/G57,NA()) -> #N/A | R57: =iferror(F57/G57,NA()) -> #N/A | S57: =J57-E57 -> -1.1 | T57: =if(E57=0,"",S57/E57) -> -1 | U57: =iferror(S57/J57,na()) -> #N/A | V57: =if(G57=0,"",E57/G57) | W57: =if(K57=0,"",E57/K57) | X57: =if(F57=0,"",(E57/F57)*100) | Y57: {=_xlfn.XLOOKUP(A57,'Video Database'!L:L,'Video Database'!M:M,"")} -> Bottom of Funnel
A58: =A57+1 -> 57 | B58: {=_xlfn.XLOOKUP(A58,'Video Database'!L:L,'Video Database'!D:D,"")} -> Erin | C58: {=_xlfn.XLOOKUP(A58,'Video Database'!L:L,'Video Database'!E:E,"")} -> Account 4 | D58: {=_xlfn.XLOOKUP(A58,'Video Database'!L:L,'Video Database'!G:G,"")} -> Stainless Steel Gua Sha | E58: {=_xlfn.XLOOKUP(A58,'Video Database'!L:L,'Video Database'!H:H,"")} -> 1.1 | F58: 0 | G58: 0 | H58: {=_xlfn.XLOOKUP(A58,'Video Database'!L:L,'Video Database'!A:A,"")} -> 46182 | I58: 46201 | J58: 0 | L58: =M58 | O58: =iferror(K58/L58, NA()) -> #N/A | P58: =iferror(G58/K58, NA()) -> #N/A | Q58: =iferror(J58/G58,NA()) -> #N/A | R58: =iferror(F58/G58,NA()) -> #N/A | S58: =J58-E58 -> -1.1 | T58: =if(E58=0,"",S58/E58) -> -1 | U58: =iferror(S58/J58,na()) -> #N/A | V58: =if(G58=0,"",E58/G58) | W58: =if(K58=0,"",E58/K58) | X58: =if(F58=0,"",(E58/F58)*100) | Y58: {=_xlfn.XLOOKUP(A58,'Video Database'!L:L,'Video Database'!M:M,"")} -> Bottom of Funnel
A59: =A58+1 -> 58 | B59: {=_xlfn.XLOOKUP(A59,'Video Database'!L:L,'Video Database'!D:D,"")} -> Erin | C59: {=_xlfn.XLOOKUP(A59,'Video Database'!L:L,'Video Database'!E:E,"")} -> Account 4 | D59: {=_xlfn.XLOOKUP(A59,'Video Database'!L:L,'Video Database'!G:G,"")} -> Stainless Steel Gua Sha | E59: {=_xlfn.XLOOKUP(A59,'Video Database'!L:L,'Video Database'!H:H,"")} -> 1.1 | F59: 0 | G59: 0 | H59: {=_xlfn.XLOOKUP(A59,'Video Database'!L:L,'Video Database'!A:A,"")} -> 46182 | I59: 46201 | J59: 0 | L59: =M59 | O59: =iferror(K59/L59, NA()) -> #N/A | P59: =iferror(G59/K59, NA()) -> #N/A | Q59: =iferror(J59/G59,NA()) -> #N/A | R59: =iferror(F59/G59,NA()) -> #N/A | S59: =J59-E59 -> -1.1 | T59: =if(E59=0,"",S59/E59) -> -1 | U59: =iferror(S59/J59,na()) -> #N/A | V59: =if(G59=0,"",E59/G59) | W59: =if(K59=0,"",E59/K59) | X59: =if(F59=0,"",(E59/F59)*100) | Y59: {=_xlfn.XLOOKUP(A59,'Video Database'!L:L,'Video Database'!M:M,"")} -> Bottom of Funnel
... A65: =A64+1 -> 64 | B65: {=_xlfn.XLOOKUP(A65,'Video Database'!L:L,'Video Database'!D:D,"")} -> Blakely | C65: {=_xlfn.XLOOKUP(A65,'Video Database'!L:L,'Video Database'!E:E,"")} -> Account 4 | D65: {=_xlfn.XLOOKUP(A65,'Video Database'!L:L,'Video Database'!G:G,"")} -> DR.DENT Purple Mouthwash | E65: {=_xlfn.XLOOKUP(A65,'Video Database'!L:L,'Video Database'!H:H,"")} -> 0.11 | F65: 0 | G65: 0 | H65: {=_xlfn.XLOOKUP(A65,'Video Database'!L:L,'Video Database'!A:A,"")} -> 46183 | I65: 46201 | J65: 0 | L65: =M65 | O65: =iferror(K65/L65, NA()) -> #N/A | P65: =iferror(G65/K65, NA()) -> #N/A | Q65: =iferror(J65/G65,NA()) -> #N/A | R65: =iferror(F65/G65,NA()) -> #N/A | S65: =J65-E65 -> -0.11 | T65: =if(E65=0,"",S65/E65) -> -1 | U65: =iferror(S65/J65,na()) -> #N/A | V65: =if(G65=0,"",E65/G65) | W65: =if(K65=0,"",E65/K65) | X65: =if(F65=0,"",(E65/F65)*100) | Y65: {=_xlfn.XLOOKUP(A65,'Video Database'!L:L,'Video Database'!M:M,"")} -> Bottom of Funnel
A66: =A65+1 -> 65 | B66: {=_xlfn.XLOOKUP(A66,'Video Database'!L:L,'Video Database'!D:D,"")} -> Blakely | C66: {=_xlfn.XLOOKUP(A66,'Video Database'!L:L,'Video Database'!E:E,"")} -> Account 4 | D66: {=_xlfn.XLOOKUP(A66,'Video Database'!L:L,'Video Database'!G:G,"")} -> DR.DENT Purple Mouthwash | E66: {=_xlfn.XLOOKUP(A66,'Video Database'!L:L,'Video Database'!H:H,"")} -> 0.11 | F66: 16.06 | G66: 1 | H66: {=_xlfn.XLOOKUP(A66,'Video Database'!L:L,'Video Database'!A:A,"")} -> 46183 | I66: 46201 | J66: 1.7 | K66: 3 | L66: =M66 -> 498 | M66: 498 | O66: =iferror(K66/L66, NA()) -> 0.0060240964 | P66: =iferror(G66/K66, NA()) -> 0.33333333 | Q66: =iferror(J66/G66,NA()) -> 1.7 | R66: =iferror(F66/G66,NA()) -> 16.06 | S66: =J66-E66 -> 1.59 | T66: =if(E66=0,"",S66/E66) -> 14.454545 | U66: =iferror(S66/J66,na()) -> 0.93529412 | V66: =if(G66=0,"",E66/G66) -> 0.11 | W66: =if(K66=0,"",E66/K66) -> 0.036666667 | X66: =if(F66=0,"",(E66/F66)*100) -> 0.68493151 | Y66: {=_xlfn.XLOOKUP(A66,'Video Database'!L:L,'Video Database'!M:M,"")} -> Bottom of Funnel
A67: =A66+1 -> 66 | B67: {=_xlfn.XLOOKUP(A67,'Video Database'!L:L,'Video Database'!D:D,"")} -> Blakely | C67: {=_xlfn.XLOOKUP(A67,'Video Database'!L:L,'Video Database'!E:E,"")} -> Account 4 | D67: {=_xlfn.XLOOKUP(A67,'Video Database'!L:L,'Video Database'!G:G,"")} -> DR.DENT Purple Mouthwash | E67: {=_xlfn.XLOOKUP(A67,'Video Database'!L:L,'Video Database'!H:H,"")} -> 0.11 | F67: 0 | G67: 0 | H67: {=_xlfn.XLOOKUP(A67,'Video Database'!L:L,'Video Database'!A:A,"")} -> 46183 | I67: 46201 | J67: 0 | L67: =M67 | O67: =iferror(K67/L67, NA()) -> #N/A | P67: =iferror(G67/K67, NA()) -> #N/A | Q67: =iferror(J67/G67,NA()) -> #N/A | R67: =iferror(F67/G67,NA()) -> #N/A | S67: =J67-E67 -> -0.11 | T67: =if(E67=0,"",S67/E67) -> -1 | U67: =iferror(S67/J67,na()) -> #N/A | V67: =if(G67=0,"",E67/G67) | W67: =if(K67=0,"",E67/K67) | X67: =if(F67=0,"",(E67/F67)*100) | Y67: {=_xlfn.XLOOKUP(A67,'Video Database'!L:L,'Video Database'!M:M,"")} -> Bottom of Funnel
A68: =A67+1 -> 67 | B68: {=_xlfn.XLOOKUP(A68,'Video Database'!L:L,'Video Database'!D:D,"")} -> Blakely | C68: {=_xlfn.XLOOKUP(A68,'Video Database'!L:L,'Video Database'!E:E,"")} -> Account 4 | D68: {=_xlfn.XLOOKUP(A68,'Video Database'!L:L,'Video Database'!G:G,"")} -> DR.DENT Purple Mouthwash | E68: {=_xlfn.XLOOKUP(A68,'Video Database'!L:L,'Video Database'!H:H,"")} -> 0.11 | F68: 0 | G68: 0 | H68: {=_xlfn.XLOOKUP(A68,'Video Database'!L:L,'Video Database'!A:A,"")} -> 46183 | I68: 46201 | J68: 0 | L68: =M68 | O68: =iferror(K68/L68, NA()) -> #N/A | P68: =iferror(G68/K68, NA()) -> #N/A | Q68: =iferror(J68/G68,NA()) -> #N/A | R68: =iferror(F68/G68,NA()) -> #N/A | S68: =J68-E68 -> -0.11 | T68: =if(E68=0,"",S68/E68) -> -1 | U68: =iferror(S68/J68,na()) -> #N/A | V68: =if(G68=0,"",E68/G68) | W68: =if(K68=0,"",E68/K68) | X68: =if(F68=0,"",(E68/F68)*100) | Y68: {=_xlfn.XLOOKUP(A68,'Video Database'!L:L,'Video Database'!M:M,"")} -> Bottom of Funnel
A69: =A68+1 -> 68 | B69: {=_xlfn.XLOOKUP(A69,'Video Database'!L:L,'Video Database'!D:D,"")} -> Blakely | C69: {=_xlfn.XLOOKUP(A69,'Video Database'!L:L,'Video Database'!E:E,"")} -> Account 4 | D69: {=_xlfn.XLOOKUP(A69,'Video Database'!L:L,'Video Database'!G:G,"")} -> DR.DENT Purple Mouthwash | E69: {=_xlfn.XLOOKUP(A69,'Video Database'!L:L,'Video Database'!H:H,"")} -> 0.11 | F69: 0 | G69: 0 | H69: {=_xlfn.XLOOKUP(A69,'Video Database'!L:L,'Video Database'!A:A,"")} -> 46183 | I69: 46201 | J69: 0 | L69: =M69 | O69: =iferror(K69/L69, NA()) -> #N/A | P69: =iferror(G69/K69, NA()) -> #N/A | Q69: =iferror(J69/G69,NA()) -> #N/A | R69: =iferror(F69/G69,NA()) -> #N/A | S69: =J69-E69 -> -0.11 | T69: =if(E69=0,"",S69/E69) -> -1 | U69: =iferror(S69/J69,na()) -> #N/A | V69: =if(G69=0,"",E69/G69) | W69: =if(K69=0,"",E69/K69) | X69: =if(F69=0,"",(E69/F69)*100) | Y69: {=_xlfn.XLOOKUP(A69,'Video Database'!L:L,'Video Database'!M:M,"")} -> Bottom of Funnel
A70: =A69+1 -> 69 | B70: {=_xlfn.XLOOKUP(A70,'Video Database'!L:L,'Video Database'!D:D,"")} -> Blakely | C70: {=_xlfn.XLOOKUP(A70,'Video Database'!L:L,'Video Database'!E:E,"")} -> Account 4 | D70: {=_xlfn.XLOOKUP(A70,'Video Database'!L:L,'Video Database'!G:G,"")} -> DR.DENT Purple Mouthwash | E70: {=_xlfn.XLOOKUP(A70,'Video Database'!L:L,'Video Database'!H:H,"")} -> 0.11 | F70: 0 | G70: 0 | H70: {=_xlfn.XLOOKUP(A70,'Video Database'!L:L,'Video Database'!A:A,"")} -> 46183 | I70: 46201 | J70: 0 | L70: =M70 | O70: =iferror(K70/L70, NA()) -> #N/A | P70: =iferror(G70/K70, NA()) -> #N/A | Q70: =iferror(J70/G70,NA()) -> #N/A | R70: =iferror(F70/G70,NA()) -> #N/A | S70: =J70-E70 -> -0.11 | T70: =if(E70=0,"",S70/E70) -> -1 | U70: =iferror(S70/J70,na()) -> #N/A | V70: =if(G70=0,"",E70/G70) | W70: =if(K70=0,"",E70/K70) | X70: =if(F70=0,"",(E70/F70)*100) | Y70: {=_xlfn.XLOOKUP(A70,'Video Database'!L:L,'Video Database'!M:M,"")} -> Bottom of Funnel
A71: =A70+1 -> 70 | B71: {=_xlfn.XLOOKUP(A71,'Video Database'!L:L,'Video Database'!D:D,"")} -> Blakely | C71: {=_xlfn.XLOOKUP(A71,'Video Database'!L:L,'Video Database'!E:E,"")} -> Account 4 | D71: {=_xlfn.XLOOKUP(A71,'Video Database'!L:L,'Video Database'!G:G,"")} -> DR.DENT Purple Mouthwash | E71: {=_xlfn.XLOOKUP(A71,'Video Database'!L:L,'Video Database'!H:H,"")} -> 0.11 | F71: 0 | G71: 0 | H71: {=_xlfn.XLOOKUP(A71,'Video Database'!L:L,'Video Database'!A:A,"")} -> 46183 | I71: 46201 | J71: 0 | L71: =M71 | O71: =iferror(K71/L71, NA()) -> #N/A | P71: =iferror(G71/K71, NA()) -> #N/A | Q71: =iferror(J71/G71,NA()) -> #N/A | R71: =iferror(F71/G71,NA()) -> #N/A | S71: =J71-E71 -> -0.11 | T71: =if(E71=0,"",S71/E71) -> -1 | U71: =iferror(S71/J71,na()) -> #N/A | V71: =if(G71=0,"",E71/G71) | W71: =if(K71=0,"",E71/K71) | X71: =if(F71=0,"",(E71/F71)*100) | Y71: {=_xlfn.XLOOKUP(A71,'Video Database'!L:L,'Video Database'!M:M,"")} -> Bottom of Funnel
A72: =A71+1 -> 71 | B72: {=_xlfn.XLOOKUP(A72,'Video Database'!L:L,'Video Database'!D:D,"")} -> Blakely | C72: {=_xlfn.XLOOKUP(A72,'Video Database'!L:L,'Video Database'!E:E,"")} -> Account 4 | D72: {=_xlfn.XLOOKUP(A72,'Video Database'!L:L,'Video Database'!G:G,"")} -> DR.DENT Purple Mouthwash | E72: {=_xlfn.XLOOKUP(A72,'Video Database'!L:L,'Video Database'!H:H,"")} -> 0.11 | F72: 0 | G72: 0 | H72: {=_xlfn.XLOOKUP(A72,'Video Database'!L:L,'Video Database'!A:A,"")} -> 46183 | I72: 46201 | J72: 0 | L72: =M72 | O72: =iferror(K72/L72, NA()) -> #N/A | P72: =iferror(G72/K72, NA()) -> #N/A | Q72: =iferror(J72/G72,NA()) -> #N/A | R72: =iferror(F72/G72,NA()) -> #N/A | S72: =J72-E72 -> -0.11 | T72: =if(E72=0,"",S72/E72) -> -1 | U72: =iferror(S72/J72,na()) -> #N/A | V72: =if(G72=0,"",E72/G72) | W72: =if(K72=0,"",E72/K72) | X72: =if(F72=0,"",(E72/F72)*100) | Y72: {=_xlfn.XLOOKUP(A72,'Video Database'!L:L,'Video Database'!M:M,"")} -> Bottom of Funnel
A73: =A72+1 -> 72 | B73: {=_xlfn.XLOOKUP(A73,'Video Database'!L:L,'Video Database'!D:D,"")} -> Blakely | C73: {=_xlfn.XLOOKUP(A73,'Video Database'!L:L,'Video Database'!E:E,"")} -> Account 4 | D73: {=_xlfn.XLOOKUP(A73,'Video Database'!L:L,'Video Database'!G:G,"")} -> DR.DENT Purple Mouthwash | E73: {=_xlfn.XLOOKUP(A73,'Video Database'!L:L,'Video Database'!H:H,"")} -> 0.11 | F73: 0 | G73: 0 | H73: {=_xlfn.XLOOKUP(A73,'Video Database'!L:L,'Video Database'!A:A,"")} -> 46183 | I73: 46201 | J73: 0 | L73: =M73 | O73: =iferror(K73/L73, NA()) -> #N/A | P73: =iferror(G73/K73, NA()) -> #N/A | Q73: =iferror(J73/G73,NA()) -> #N/A | R73: =iferror(F73/G73,NA()) -> #N/A | S73: =J73-E73 -> -0.11 | T73: =if(E73=0,"",S73/E73) -> -1 | U73: =iferror(S73/J73,na()) -> #N/A | V73: =if(G73=0,"",E73/G73) | W73: =if(K73=0,"",E73/K73) | X73: =if(F73=0,"",(E73/F73)*100) | Y73: {=_xlfn.XLOOKUP(A73,'Video Database'!L:L,'Video Database'!M:M,"")} -> Bottom of Funnel
A74: =A73+1 -> 73 | B74: {=_xlfn.XLOOKUP(A74,'Video Database'!L:L,'Video Database'!D:D,"")} -> Blakely | C74: {=_xlfn.XLOOKUP(A74,'Video Database'!L:L,'Video Database'!E:E,"")} -> Account 4 | D74: {=_xlfn.XLOOKUP(A74,'Video Database'!L:L,'Video Database'!G:G,"")} -> DR.DENT Purple Mouthwash | E74: {=_xlfn.XLOOKUP(A74,'Video Database'!L:L,'Video Database'!H:H,"")} -> 0.11 | F74: 0 | G74: 0 | H74: {=_xlfn.XLOOKUP(A74,'Video Database'!L:L,'Video Database'!A:A,"")} -> 46183 | I74: 46201 | J74: 0 | L74: =M74 | O74: =iferror(K74/L74, NA()) -> #N/A | P74: =iferror(G74/K74, NA()) -> #N/A | Q74: =iferror(J74/G74,NA()) -> #N/A | R74: =iferror(F74/G74,NA()) -> #N/A | S74: =J74-E74 -> -0.11 | T74: =if(E74=0,"",S74/E74) -> -1 | U74: =iferror(S74/J74,na()) -> #N/A | V74: =if(G74=0,"",E74/G74) | W74: =if(K74=0,"",E74/K74) | X74: =if(F74=0,"",(E74/F74)*100) | Y74: {=_xlfn.XLOOKUP(A74,'Video Database'!L:L,'Video Database'!M:M,"")} -> Bottom of Funnel
A75: =A74+1 -> 74 | B75: {=_xlfn.XLOOKUP(A75,'Video Database'!L:L,'Video Database'!D:D,"")} -> Blakely | C75: {=_xlfn.XLOOKUP(A75,'Video Database'!L:L,'Video Database'!E:E,"")} -> Account 4 | D75: {=_xlfn.XLOOKUP(A75,'Video Database'!L:L,'Video Database'!G:G,"")} -> DR.DENT Purple Mouthwash | E75: {=_xlfn.XLOOKUP(A75,'Video Database'!L:L,'Video Database'!H:H,"")} -> 0.11 | F75: 0 | G75: 0 | H75: {=_xlfn.XLOOKUP(A75,'Video Database'!L:L,'Video Database'!A:A,"")} -> 46183 | I75: 46201 | J75: 0 | L75: =M75 | O75: =iferror(K75/L75, NA()) -> #N/A | P75: =iferror(G75/K75, NA()) -> #N/A | Q75: =iferror(J75/G75,NA()) -> #N/A | R75: =iferror(F75/G75,NA()) -> #N/A | S75: =J75-E75 -> -0.11 | T75: =if(E75=0,"",S75/E75) -> -1 | U75: =iferror(S75/J75,na()) -> #N/A | V75: =if(G75=0,"",E75/G75) | W75: =if(K75=0,"",E75/K75) | X75: =if(F75=0,"",(E75/F75)*100) | Y75: {=_xlfn.XLOOKUP(A75,'Video Database'!L:L,'Video Database'!M:M,"")} -> Bottom of Funnel
A76: =A75+1 -> 75 | B76: {=_xlfn.XLOOKUP(A76,'Video Database'!L:L,'Video Database'!D:D,"")} -> Blakely | C76: {=_xlfn.XLOOKUP(A76,'Video Database'!L:L,'Video Database'!E:E,"")} -> Account 4 | D76: {=_xlfn.XLOOKUP(A76,'Video Database'!L:L,'Video Database'!G:G,"")} -> DR.DENT Purple Mouthwash | E76: {=_xlfn.XLOOKUP(A76,'Video Database'!L:L,'Video Database'!H:H,"")} -> 0.11 | F76: 0 | G76: 0 | H76: {=_xlfn.XLOOKUP(A76,'Video Database'!L:L,'Video Database'!A:A,"")} -> 46183 | I76: 46201 | J76: 0 | L76: =M76 | O76: =iferror(K76/L76, NA()) -> #N/A | P76: =iferror(G76/K76, NA()) -> #N/A | Q76: =iferror(J76/G76,NA()) -> #N/A | R76: =iferror(F76/G76,NA()) -> #N/A | S76: =J76-E76 -> -0.11 | T76: =if(E76=0,"",S76/E76) -> -1 | U76: =iferror(S76/J76,na()) -> #N/A | V76: =if(G76=0,"",E76/G76) | W76: =if(K76=0,"",E76/K76) | X76: =if(F76=0,"",(E76/F76)*100) | Y76: {=_xlfn.XLOOKUP(A76,'Video Database'!L:L,'Video Database'!M:M,"")} -> Bottom of Funnel
...

Sheet Pivot Tables
G1: Video # | H1: Creator | I1: Account | J1: Product | K1: Orders | L1: Commission | M1: Profit | N1: ROI | V1: ROI | W1: Cost per Order | X1: Commission Per Video | Y1: Profit Per Video
G2: =IFERROR(__xludf.DUMMYFUNCTION("ARRAY_CONSTRAIN( CHOOSECOLS( SORT( FILTER( 'Performance Data'!A2:X2235, 'Performance Data'!A2:A2235<>"""", 'Performance Data'!B2:B2235<>"""" ), 19, FALSE ), 1,2,3,4,7,10,19,20 ), 10, 8 )"),1146.0) -> 1146 | H2: =IFERROR(__xludf.DUMMYFUNCTION("""COMPUTED_VALUE"""),"Sierra") -> Sierra | I2: =IFERROR(__xludf.DUMMYFUNCTION("""COMPUTED_VALUE"""),"Account 4") -> Account 4 | J2: =IFERROR(__xludf.DUMMYFUNCTION("""COMPUTED_VALUE"""),"Taste Salud Skin + Beauty Drink Mix") -> Taste Salud Skin + Beauty Drink Mix | K2: =IFERROR(__xludf.DUMMYFUNCTION("""COMPUTED_VALUE"""),2.0) -> 2 | L2: =IFERROR(__xludf.DUMMYFUNCTION("""COMPUTED_VALUE"""),14.57) -> 14.57 | M2: =IFERROR(__xludf.DUMMYFUNCTION("""COMPUTED_VALUE"""),13.47) -> 13.47 | N2: =IFERROR(__xludf.DUMMYFUNCTION("""COMPUTED_VALUE"""),12.245454545454544) -> 12.245455 | V2: =if(S2=0,"",T2/S2) -> 0.70309478 | W2: =if(U2=0,"",S2/U2) -> 1.6832558 | X2: =if(Q2=0,"",R2/Q2) -> 0.18734043 | Y2: =if(Q2=0,"",T2/Q2) -> 0.077340426
G3: =IFERROR(__xludf.DUMMYFUNCTION("""COMPUTED_VALUE"""),901.0) -> 901 | H3: =IFERROR(__xludf.DUMMYFUNCTION("""COMPUTED_VALUE"""),"Blakely") -> Blakely | I3: =IFERROR(__xludf.DUMMYFUNCTION("""COMPUTED_VALUE"""),"Account 4") -> Account 4 | J3: =IFERROR(__xludf.DUMMYFUNCTION("""COMPUTED_VALUE"""),"JOYMODE Ignite Libido Support") -> JOYMODE Ignite Libido Support | K3: =IFERROR(__xludf.DUMMYFUNCTION("""COMPUTED_VALUE"""),4.0) -> 4 | L3: =IFERROR(__xludf.DUMMYFUNCTION("""COMPUTED_VALUE"""),13.2) -> 13.2 | M3: =IFERROR(__xludf.DUMMYFUNCTION("""COMPUTED_VALUE"""),13.09) -> 13.09 | N3: =IFERROR(__xludf.DUMMYFUNCTION("""COMPUTED_VALUE"""),119.0) -> 119 | V3: =if(S3=0,"",T3/S3) -> -0.91880706 | W3: =if(U3=0,"",S3/U3) -> 41.85093 | X3: =if(Q3=0,"",R3/Q3) -> 0.066237817 | Y3: =if(Q3=0,"",T3/Q3) -> -0.74956979
G4: =IFERROR(__xludf.DUMMYFUNCTION("""COMPUTED_VALUE"""),299.0) -> 299 | H4: =IFERROR(__xludf.DUMMYFUNCTION("""COMPUTED_VALUE"""),"Blakely") -> Blakely | I4: =IFERROR(__xludf.DUMMYFUNCTION("""COMPUTED_VALUE"""),"Account 2") -> Account 2 | J4: =IFERROR(__xludf.DUMMYFUNCTION("""COMPUTED_VALUE"""),"Beast Bites Creatine Gummies") -> Beast Bites Creatine Gummies | K4: =IFERROR(__xludf.DUMMYFUNCTION("""COMPUTED_VALUE"""),5.0) -> 5 | L4: =IFERROR(__xludf.DUMMYFUNCTION("""COMPUTED_VALUE"""),11.84) -> 11.84 | M4: =IFERROR(__xludf.DUMMYFUNCTION("""COMPUTED_VALUE"""),11.73) -> 11.73 | N4: =IFERROR(__xludf.DUMMYFUNCTION("""COMPUTED_VALUE"""),106.63636363636364) -> 106.63636 | V4: =if(S4=0,"",T4/S4) -> -0.68643579 | W4: =if(U4=0,"",S4/U4) -> 17.325 | X4: =if(Q4=0,"",R4/Q4) -> 0.34492063 | Y4: =if(Q4=0,"",T4/Q4) -> -0.75507937
G5: =IFERROR(__xludf.DUMMYFUNCTION("""COMPUTED_VALUE"""),634.0) -> 634 | H5: =IFERROR(__xludf.DUMMYFUNCTION("""COMPUTED_VALUE"""),"Blakely") -> Blakely | I5: =IFERROR(__xludf.DUMMYFUNCTION("""COMPUTED_VALUE"""),"Account 2") -> Account 2 | J5: =IFERROR(__xludf.DUMMYFUNCTION("""COMPUTED_VALUE"""),"JOYMODE Ignite Libido Support") -> JOYMODE Ignite Libido Support | K5: =IFERROR(__xludf.DUMMYFUNCTION("""COMPUTED_VALUE"""),2.0) -> 2 | L5: =IFERROR(__xludf.DUMMYFUNCTION("""COMPUTED_VALUE"""),8.8) -> 8.8 | M5: =IFERROR(__xludf.DUMMYFUNCTION("""COMPUTED_VALUE"""),8.690000000000001) -> 8.69 | N5: =IFERROR(__xludf.DUMMYFUNCTION("""COMPUTED_VALUE"""),79.00000000000001) -> 79 | V5: =if(S5=0,"",T5/S5) -> -0.50651629 | W5: =if(U5=0,"",S5/U5) -> 3.99 | X5: =if(Q5=0,"",R5/Q5) -> 0.16789922 | Y5: =if(Q5=0,"",T5/Q5) -> -0.17233333
G6: =IFERROR(__xludf.DUMMYFUNCTION("""COMPUTED_VALUE"""),734.0) -> 734 | H6: =IFERROR(__xludf.DUMMYFUNCTION("""COMPUTED_VALUE"""),"Brittney") -> Brittney | I6: =IFERROR(__xludf.DUMMYFUNCTION("""COMPUTED_VALUE"""),"Account 4") -> Account 4 | J6: =IFERROR(__xludf.DUMMYFUNCTION("""COMPUTED_VALUE"""),"Gruns Greens Popsicle Firecracker Gummies") -> Gruns Greens Popsicle Firecracker Gummies | K6: =IFERROR(__xludf.DUMMYFUNCTION("""COMPUTED_VALUE"""),4.0) -> 4 | L6: =IFERROR(__xludf.DUMMYFUNCTION("""COMPUTED_VALUE"""),8.59) -> 8.59 | M6: =IFERROR(__xludf.DUMMYFUNCTION("""COMPUTED_VALUE"""),8.48) -> 8.48 | N6: =IFERROR(__xludf.DUMMYFUNCTION("""COMPUTED_VALUE"""),77.0909090909091) -> 77.090909 | V6: =if(S6=0,"",T6/S6) -> -1 | W6: =if(U6=0,"",S6/U6) | X6: =if(Q6=0,"",R6/Q6) -> 0 | Y6: =if(Q6=0,"",T6/Q6) -> -1.1
G7: =IFERROR(__xludf.DUMMYFUNCTION("""COMPUTED_VALUE"""),1013.0) -> 1013 | H7: =IFERROR(__xludf.DUMMYFUNCTION("""COMPUTED_VALUE"""),"Blakely") -> Blakely | I7: =IFERROR(__xludf.DUMMYFUNCTION("""COMPUTED_VALUE"""),"Account 3") -> Account 3 | J7: =IFERROR(__xludf.DUMMYFUNCTION("""COMPUTED_VALUE"""),"tarte CC Color-Correct Tinted Serum") -> tarte CC Color-Correct Tinted Serum | K7: =IFERROR(__xludf.DUMMYFUNCTION("""COMPUTED_VALUE"""),1.0) -> 1 | L7: =IFERROR(__xludf.DUMMYFUNCTION("""COMPUTED_VALUE"""),7.2) -> 7.2 | M7: =IFERROR(__xludf.DUMMYFUNCTION("""COMPUTED_VALUE"""),7.09) -> 7.09 | N7: =IFERROR(__xludf.DUMMYFUNCTION("""COMPUTED_VALUE"""),64.45454545454545) -> 64.454545 | V7: =if(S7=0,"",T7/S7) -> -1 | W7: =if(U7=0,"",S7/U7) | X7: =if(Q7=0,"",R7/Q7) -> 0 | Y7: =if(Q7=0,"",T7/Q7) -> -1.1
G8: =IFERROR(__xludf.DUMMYFUNCTION("""COMPUTED_VALUE"""),725.0) -> 725 | H8: =IFERROR(__xludf.DUMMYFUNCTION("""COMPUTED_VALUE"""),"Blakely") -> Blakely | I8: =IFERROR(__xludf.DUMMYFUNCTION("""COMPUTED_VALUE"""),"Account 3") -> Account 3 | J8: =IFERROR(__xludf.DUMMYFUNCTION("""COMPUTED_VALUE"""),"Swanson Full Spectrum Spearmint Leaf") -> Swanson Full Spectrum Spearmint Leaf | K8: =IFERROR(__xludf.DUMMYFUNCTION("""COMPUTED_VALUE"""),1.0) -> 1 | L8: =IFERROR(__xludf.DUMMYFUNCTION("""COMPUTED_VALUE"""),7.12) -> 7.12 | M8: =IFERROR(__xludf.DUMMYFUNCTION("""COMPUTED_VALUE"""),7.01) -> 7.01 | N8: =IFERROR(__xludf.DUMMYFUNCTION("""COMPUTED_VALUE"""),63.72727272727273) -> 63.727273
G9: =IFERROR(__xludf.DUMMYFUNCTION("""COMPUTED_VALUE"""),1065.0) -> 1065 | H9: =IFERROR(__xludf.DUMMYFUNCTION("""COMPUTED_VALUE"""),"Blakely") -> Blakely | I9: =IFERROR(__xludf.DUMMYFUNCTION("""COMPUTED_VALUE"""),"Account 4") -> Account 4 | J9: =IFERROR(__xludf.DUMMYFUNCTION("""COMPUTED_VALUE"""),"IRIS Hormone Health Drink Mix") -> IRIS Hormone Health Drink Mix | K9: =IFERROR(__xludf.DUMMYFUNCTION("""COMPUTED_VALUE"""),2.0) -> 2 | L9: =IFERROR(__xludf.DUMMYFUNCTION("""COMPUTED_VALUE"""),5.93) -> 5.93 | M9: =IFERROR(__xludf.DUMMYFUNCTION("""COMPUTED_VALUE"""),5.819999999999999) -> 5.82 | N9: =IFERROR(__xludf.DUMMYFUNCTION("""COMPUTED_VALUE"""),52.90909090909091) -> 52.909091
G10: =IFERROR(__xludf.DUMMYFUNCTION("""COMPUTED_VALUE"""),1348.0) -> 1348 | H10: =IFERROR(__xludf.DUMMYFUNCTION("""COMPUTED_VALUE"""),"Sierra") -> Sierra | I10: =IFERROR(__xludf.DUMMYFUNCTION("""COMPUTED_VALUE"""),"Account 4") -> Account 4 | J10: =IFERROR(__xludf.DUMMYFUNCTION("""COMPUTED_VALUE"""),"Taste Salud Skin + Beauty Drink Mix") -> Taste Salud Skin + Beauty Drink Mix | K10: =IFERROR(__xludf.DUMMYFUNCTION("""COMPUTED_VALUE"""),1.0) -> 1 | L10: =IFERROR(__xludf.DUMMYFUNCTION("""COMPUTED_VALUE"""),5.76) -> 5.76 | M10: =IFERROR(__xludf.DUMMYFUNCTION("""COMPUTED_VALUE"""),4.66) -> 4.66 | N10: =IFERROR(__xludf.DUMMYFUNCTION("""COMPUTED_VALUE"""),4.236363636363636) -> 4.2363636 | Z10: ROI
G11: =IFERROR(__xludf.DUMMYFUNCTION("""COMPUTED_VALUE"""),451.0) -> 451 | H11: =IFERROR(__xludf.DUMMYFUNCTION("""COMPUTED_VALUE"""),"Blakely") -> Blakely | I11: =IFERROR(__xludf.DUMMYFUNCTION("""COMPUTED_VALUE"""),"Account 3") -> Account 3 | J11: =IFERROR(__xludf.DUMMYFUNCTION("""COMPUTED_VALUE"""),"Cutler Nutrition Liquid Carnitine 3000") -> Cutler Nutrition Liquid Carnitine 3000 | K11: =IFERROR(__xludf.DUMMYFUNCTION("""COMPUTED_VALUE"""),1.0) -> 1 | L11: =IFERROR(__xludf.DUMMYFUNCTION("""COMPUTED_VALUE"""),4.5) -> 4.5 | M11: =IFERROR(__xludf.DUMMYFUNCTION("""COMPUTED_VALUE"""),4.39) -> 4.39 | N11: =IFERROR(__xludf.DUMMYFUNCTION("""COMPUTED_VALUE"""),39.90909090909091) -> 39.909091 | Z11: =if(X11=0,"",X11/W11) -> -0.58239696
Z12: =if(X12=0,"",X12/W12) -> -0.83591228
Z13: =if(X13=0,"",X13/W13) -> -0.74902162
N14: ROI | O14: Profit Per Video | P14: Cost per Order | Q14: Commission Per Video | R14: Videos per Order | Z14: =if(X14=0,"",X14/W14) -> -0.66256006
N15: =if(L15=0,"",M15/L15) -> 14.897727 | O15: =if(H15=0,"",M15/H15) -> 1.63875 | P15: =if(I15=0,"",L15/I15) -> 0.19555556 | Q15: =if(H15=0,"",K15/H15) -> 1.74875 | R15: =if(I15=0,"",H15/I15) -> 1.7777778
N16: =if(L16=0,"",M16/L16) -> 4.8651026 | O16: =if(H16=0,"",M16/H16) -> 0.53516129 | P16: =if(I16=0,"",L16/I16) -> 0.56833333 | Q16: =if(H16=0,"",K16/H16) -> 0.64516129 | R16: =if(I16=0,"",H16/I16) -> 5.1666667
N17: =if(L17=0,"",M17/L17) -> 2.1422925 | O17: =if(H17=0,"",M17/H17) -> 0.23565217 | P17: =if(I17=0,"",L17/I17) -> 1.012 | Q17: =if(H17=0,"",K17/H17) -> 0.34565217 | R17: =if(I17=0,"",H17/I17) -> 9.2 | T17: Content Style | U17: Videos | V17: Commission | W17: Cost | X17: Profit | Y17: Orders | Z17: ROI
N18: =if(L18=0,"",M18/L18) -> 2.2727273 | O18: =if(H18=0,"",M18/H18) -> 0.25 | P18: =if(I18=0,"",L18/I18) -> 1.4666667 | Q18: =if(H18=0,"",K18/H18) -> 0.36 | R18: =if(I18=0,"",H18/I18) -> 13.333333 | T18: Bottom of Funnel | U18: 833 | V18: 77.75 | W18: 485.3893 | X18: -407.6393 | Y18: 27 | Z18: =if(X18=0,"",X18/W18) -> -0.8398193
N19: =if(L19=0,"",M19/L19) -> 1.5957447 | O19: =if(H19=0,"",M19/H19) -> 0.17553191 | P19: =if(I19=0,"",L19/I19) -> 0.86166667 | Q19: =if(H19=0,"",K19/H19) -> 0.28553191 | R19: =if(I19=0,"",H19/I19) -> 7.8333333 | T19: Middle of Funnel | U19: 144 | V19: 21.73 | W19: 104.94 | X19: -83.21 | Y19: 4 | Z19: =if(X19=0,"",X19/W19) -> -0.79292929
N20: =if(L20=0,"",M20/L20) -> 7.0909091 | O20: =if(H20=0,"",M20/H20) -> 0.78 | P20: =if(I20=0,"",L20/I20) -> 0.88 | Q20: =if(H20=0,"",K20/H20) -> 0.89 | R20: =if(I20=0,"",H20/I20) -> 8 | T20: Product Overlay | U20: 415 | V20: 101.159 | W20: 45.65 | X20: 55.509 | Y20: 37 | Z20: =if(X20=0,"",X20/W20) -> 1.2159693
N21: =if(L21=0,"",M21/L21) -> 7.1818182 | O21: =if(H21=0,"",M21/H21) -> 0.79 | P21: =if(I21=0,"",L21/I21) -> 0.55 | Q21: =if(H21=0,"",K21/H21) -> 0.9 | R21: =if(I21=0,"",H21/I21) -> 5
N22: =if(L22=0,"",M22/L22) -> 2.9848485 | O22: =if(H22=0,"",M22/H22) -> 0.32833333 | P22: =if(I22=0,"",L22/I22) -> 0.33 | Q22: =if(H22=0,"",K22/H22) -> 0.43833333 | R22: =if(I22=0,"",H22/I22) -> 3
N23: =if(L23=0,"",M23/L23) -> 3.0909091 | O23: =if(H23=0,"",M23/H23) -> 0.34 | P23: =if(I23=0,"",L23/I23) -> 0.88 | Q23: =if(H23=0,"",K23/H23) -> 0.45 | R23: =if(I23=0,"",H23/I23) -> 8
N24: =if(L24=0,"",M24/L24) -> 0.81818182 | O24: =if(H24=0,"",M24/H24) -> 0.09 | P24: =if(I24=0,"",L24/I24) -> 0.55 | Q24: =if(H24=0,"",K24/H24) -> 0.2 | R24: =if(I24=0,"",H24/I24) -> 5
N25: =if(L25=0,"",M25/L25) -> 0.18181818 | O25: =if(H25=0,"",M25/H25) -> 0.02 | P25: =if(I25=0,"",L25/I25) -> 0.88 | Q25: =if(H25=0,"",K25/H25) -> 0.13 | R25: =if(I25=0,"",H25/I25) -> 8
N26: =if(L26=0,"",M26/L26) -> -0.18660287 | O26: =if(H26=0,"",M26/H26) -> -0.020526316 | P26: =if(I26=0,"",L26/I26) -> 2.09 | Q26: =if(H26=0,"",K26/H26) -> 0.089473684 | R26: =if(I26=0,"",H26/I26) -> 19
N27: =if(L27=0,"",M27/L27) -> -1 | O27: =if(H27=0,"",M27/H27) -> -0.11 | P27: =if(I27=0,"",L27/I27) | Q27: =if(H27=0,"",K27/H27) -> 0 | R27: =if(I27=0,"",H27/I27)
N28: =if(L28=0,"",M28/L28) -> -1 | O28: =if(H28=0,"",M28/H28) -> -0.11 | P28: =if(I28=0,"",L28/I28) | Q28: =if(H28=0,"",K28/H28) -> 0 | R28: =if(I28=0,"",H28/I28)
N29: =if(L29=0,"",M29/L29) -> -1 | O29: =if(H29=0,"",M29/H29) -> -0.11 | P29: =if(I29=0,"",L29/I29) | Q29: =if(H29=0,"",K29/H29) -> 0 | R29: =if(I29=0,"",H29/I29)
N30: =if(L30=0,"",M30/L30) -> -1 | O30: =if(H30=0,"",M30/H30) -> -0.11 | P30: =if(I30=0,"",L30/I30) | Q30: =if(H30=0,"",K30/H30) -> 0 | R30: =if(I30=0,"",H30/I30)
N31: =if(L31=0,"",M31/L31) -> -1 | O31: =if(H31=0,"",M31/H31) -> -0.11 | P31: =if(I31=0,"",L31/I31) | Q31: =if(H31=0,"",K31/H31) -> 0 | R31: =if(I31=0,"",H31/I31)
N32: =if(L32=0,"",M32/L32) -> -1 | O32: =if(H32=0,"",M32/H32) -> -0.11 | P32: =if(I32=0,"",L32/I32) | Q32: =if(H32=0,"",K32/H32) -> 0 | R32: =if(I32=0,"",H32/I32)
